Workbook

Sheet 2025
A1: Auftragsbuch 2025 – Brenner Haustechnik
A2: Stand 15.10.2026
A3: Auftr.-Nr. | B3: Datum | C3: Kd-Nr | D3: Kunde | E3: Objekt / Einsatzort | F3: Art | G3: Beschreibung | H3: Monteur | I3: Status | J3: Wert netto | K3: erledigt am | L3: Rechnung
A4: A-25-001 | B4: 45660 | C4: 10097 | D4: Berger, Ramona | E4: Teplitzer Straße 163 | F4: Wartung | G4: Wartung Ölheizung | H4: DH | I4: abgerechnet | J4: 139,00 € | K4: 45666 | L4: RE-2025-0005
A5: A-25-002 | B5: 45660 | C5: 10126 | D5: Lange, Florian | E5: Königsbrücker Straße 101 | F5: Reparatur | G5: Austausch Thermostatventil | H5: JK | I5: abgerechnet | J5: 394 | K5: 45663
A6: A-25-003 | B6: 45663 | C6: 10027 | D6: Hausverwaltung Kröber | E6: Nürnberger Straße 73 | F6: Notdienst | G6: Verstopfung Grundleitung | H6: AY | I6: abgerechnet | J6: 468 | K6: 45666 | L6: RE-2025-0006
A7: A-25-004 | B7: 45663 | C7: 10050 | D7: WEG-Verwaltung Blasewitz GmbH | E7: Prießnitzstraße 111 | F7: Reparatur | G7: Zirkulationspumpe defekt | H7: MR | I7: abgerechnet | J7: ca. 910 | K7: 45664 | L7: RE-2025-0001
A8: A-25-005 | B8: 45663 | C8: 10107 | D8: Fr. Ebert | E8: Kesselsdorfer Straße 124 | F8: Badsanierung | G8: Badumbau barrierefrei | H8: MR/KS | I8: abgerechnet | J8: 19342 | K8: 45686 | L8: RE-2025-0003, RE-2025-0021
A9: A-25-006 | B9: 45665 | D9: Lange, Florian | E9: Königsbrücker Straße 101 | F9: Heizungstausch | G9: Einbau Wärmepumpe Luft/Wasser | H9: AY/KS | I9: abgerechnet | J9: 11147 | K9: 45685
A10: A-25-007 | B10: 45667 | D10: Bauer, Claudia | E10: Karcherallee 122 | F10: Heizungstausch | G10: Einbau Wärmepumpe Luft/Wasser | H10: DH | I10: abgerechnet | J10: 13686 | K10: 45685 | L10: RE-2025-0007, RE-2025-0015
A11: A-25-008 | B11: 45670 | C11: 10014 | D11: Hofmann, Klaus | E11: Borsbergstraße 22 | F11: Montage | G11: Montage Wand-WC | H11: MR | I11: storniert | J11: ca. 1070
A12: A-25-009 | B12: 45671 | C12: 10082 | D12: Städtische Wohnungsgesellschaft Freital mbH | E12: Hamburger Straße 23 | F12: Notdienst | G12: Rohrbruch Küche | H12: AY | I12: abgerechnet | J12: 271 | K12: 45672 | L12: RE-2025-0008
A13: A-25-010 | B13: 45672 | C13: 10057 | D13: Neumann, Kerstin | E13: Stauffenbergallee 92a | F13: Heizungstausch | G13: Austausch Gaskessel gegen Brennwert | H13: DH | I13: erledigt | J13: 16011 | K13: 45701
A14: A-25-011 | B14: 45677 | C14: 10013 | D14: Immobilienverwaltung Weißer Hirsch GmbH | E14: Rudolf-Leonhard-Straße 3 | F14: Wartung | G14: Jahreswartung Gastherme | H14: JK | I14: abgerechnet | J14: 139 | K14: KW 4 | L14: RE-2025-0009
A15: A-25-012 | B15: 45678 | C15: 10070 | D15: Bäckerei Hoffmann | E15: Königsbrücker Straße 56 | F15: Montage | G15: Montage Waschtisch | H15: DH | I15: abgerechnet | J15: ca. 1680 | K15: 45680 | L15: RE-2025-0013
A16: A-25-013 | B16: 45678 | C16: 10070 | D16: Bäckerei Hoffmann | E16: Königsbrücker Straße 56 | F16: Wartung | G16: Wartung Gas-Brennwertkessel | H16: DH | I16: abgerechnet | J16: 189 | K16: 45681 | L16: RE-2025-0011
A17: A-25-014 | B17: 45678 | C17: 10077 | D17: Schwarz, Ralf | E17: Görlitzer Straße 121 | F17: Heizungstausch | G17: Einbau Wärmepumpe Luft/Wasser | H17: MR/KS | I17: abgerechnet | J17: 10019 | K17: 45727 | L17: RE-2025-0012, RE-2025-0050
A18: A-25-015 | B18: 45680 | C18: 10050 | D18: WEG-Verwaltung Blasewitz | E18: Prießnitzstraße 111 | F18: Notdienst | G18: Rohrbruch Küche | H18: AY | I18: storniert
A19: A-25-016 | B19: 45680 | C19: 10114 | D19: Fr. Seidel | E19: Meißner Landstraße 51 | F19: Wartung | G19: Wartung Ölheizung | H19: JK | I19: abgerechnet | J19: 139 | K19: 45681 | L19: RE-2025-0017
A20: A-25-017 | B20: 45684 | C20: 10011 | D20: Wagner, Volker | E20: Pillnitzer Landstraße 80a | F20: Notdienst | G20: Heizungsausfall Wochenende | H20: JK | I20: abgerechnet | J20: 197 | K20: 45684 | L20: RE-2025-0014
A21: A-25-018 | B21: 45686 | C21: 10030 | D21: Autohaus Pieschen | E21: Bergstraße 11 | F21: Reparatur | G21: Druckverlust Heizung | H21: DH | I21: abgerechnet | J21: 123 | K21: 45686 | L21: RE-2025-0022
A22: A-25-019 | B22: 45687 | C22: 10050 | D22: WEG-Verwaltung Blasewitz GmbH | E22: Martin-Luther-Straße 55 | F22: Wartung | G22: Wartung Gas-Brennwertkessel | H22: AY | I22: abgerechnet | J22: 149 | K22: 45693
A23: A-25-020 | B23: 45688 | C23: 10024 | D23: Mirko Vogel | E23: Cossebauder Straße 10 | F23: Wartung | G23: Wartung Gas-Brennwertkessel | H23: AY | I23: abgerechnet | J23: 189 | K23: 45688 | L23: RE-2025-0024
A24: A-25-021 | B24: 45688 | C24: 10041 | D24: Fitnessstudio ElbeFit GmbH | E24: Bahnhofstraße 142 | F24: Wartung | G24: Wartung Wärmepumpe | H24: JK | I24: abgerechnet | J24: 149 | K24: 45694 | L24: RE-2025-0020
A25: A-25-022 | B25: 45688 | C25: 10100 | D25: Krause, Anja | E25: Prießnitzstraße 174 | F25: Montage | G25: Austausch Warmwasserspeicher | H25: MR | I25: abgerechnet | J25: ca. 1710 | K25: 45691 | L25: RE-2025-0023
D26: Summe Januar 2025 | J26: =SUBTOTAL(9,J4:J25) -> 72612
A28: A-25-023 | B28: 45691 | C28: 10023 | D28: Müller GmbH & Co. KG | E28: Großenhainer Straße 101 | F28: Wartung | G28: Wartung Ölheizung | H28: JK | I28: abgerechnet | J28: 139 | K28: 45693
A29: A-25-024 | B29: 45691 | C29: 10069 | D29: Schröder, Kerstin | E29: Tharandter Straße 103a | F29: Montage | G29: Austausch Warmwasserspeicher | H29: JK | I29: abgerechnet | J29: 1297 | K29: 45694 | L29: RE-2025-0030
A30: A-25-025 | B30: 45691 | C30: 10075 | D30: Engel, Rainer | E30: Nürnberger Straße 9 | F30: Montage | G30: Montage Waschtisch | H30: AY | I30: abgerechnet | J30: 635 | K30: 45692 | L30: RE-2025-0016
A31: A-25-026 | B31: 45691 | C31: 10109 | D31: Horn, Sandra | E31: Bergstraße 39a | F31: Heizungstausch | G31: Austausch Gaskessel gegen Brennwert | H31: MR/KS | I31: abgerechnet | J31: 13434 | K31: 45736 | L31: RE-2025-0025, RE-2025-0055
A32: A-25-027 | B32: 45692 | C32: 10005 | D32: WG Elbtal eG | E32: Harthaer Straße 7 | F32: Reparatur | G32: Heizung ohne Funktion | H32: JK | I32: abgerechnet | J32: 866 | K32: 45693 | L32: RE-2025-0019
A33: A-25-028 | B33: 45692 | C33: 10085 | D33: Fr. Horn | E33: Kesselsdorfer Straße 116 | F33: Heizungstausch | G33: Heizungsmodernisierung | H33: DH | I33: abgerechnet | J33: 15604 | K33: 45715 | L33: RE-2025-0028, RE-2025-0041
A34: A-25-029 | B34: 45698 | C34: 10030 | D34: Autohaus Pieschen GmbH | E34: Bergstraße 11 | F34: Reparatur | G34: Spülkasten läuft nach | H34: DH | I34: abgerechnet | J34: 402 | K34: KW 7 | L34: RE-2025-0027
A35: A-25-030 | B35: 45698 | D35: Neumann, Anett | E35: Rudolf-Leonhard-Straße 147 | F35: Montage | G35: Montage Wand-WC | H35: AY | I35: abgerechnet | J35: 820 | K35: 45698 | L35: RE-2025-0034
A36: A-25-031 | B36: 45698 | D36: Ebert, Anja | E36: Hamburger Straße 97 | F36: Heizungstausch | G36: Heizungsmodernisierung | H36: DH | I36: abgerechnet | J36: 13.880,00 € | K36: 45730 | L36: RE-2025-0031, RE-2025-0054
A37: A-25-032 | B37: 45699 | C37: 10014 | D37: Hofmann, Klaus | E37: Borsbergstraße 22 | F37: Wartung | G37: Wartung Wärmepumpe | H37: JK | I37: abgerechnet | J37: 139 | K37: 45705 | L37: RE-2025-0037
A38: A-25-033 | B38: 45699 | C38: 10104 | D38: Gaststätte Zur Linde | E38: Nürnberger Straße 164 | F38: Montage | G38: Einbau Enthärtungsanlage | H38: AY | I38: abgerechnet | J38: ca. 1720 | K38: KW 7 | L38: RE-2025-0033
A39: A-25-034 | B39: 45700 | C39: 10072 | D39: Kindergarten Elbspatzen e.V. | E39: Königsbrücker Straße 33b | F39: Wartung | G39: Wartung Wärmepumpe | H39: MR | I39: storniert
A40: A-25-035 | B40: 45701 | C40: 10062 | D40: Uhlig, Jörg | E40: Martin-Luther-Straße 99b | F40: Montage | G40: Montage Heizkörper | H40: JK | I40: abgerechnet | J40: 700 | K40: 45705
A41: A-25-036 | B41: 45702 | D41: Mirko Vogel | E41: Cossebauder Straße 10 | F41: Badsanierung | G41: Gäste-WC Sanierung | H41: AY/KS | I41: abgerechnet | J41: 15827 | K41: 45747 | L41: RE-2025-0032, RE-2025-0064
...

Sheet 2026
A1: Auftragsbuch 2026 – Brenner Haustechnik
A2: Stand 15.10.2026
A3: Auftr.-Nr. | B3: Datum | C3: Kd-Nr | D3: Kunde | E3: Objekt / Einsatzort | F3: Art | G3: Beschreibung | H3: Monteur | I3: Status | J3: Wert netto | K3: erledigt am | L3: Rechnung
A4: A-26-001 | B4: 46027 | C4: 10010 | D4: Hr. Wagner | E4: Cossebauder Straße 58 | F4: Montage | G4: Montage Heizkörper | H4: AY | I4: abgerechnet | J4: 1752 | K4: 46031
A5: A-26-002 | B5: 05.01.2026 | D5: Neumann, Kerstin | E5: Stauffenbergallee 92a | F5: Wartung | G5: Jahreswartung Gastherme | H5: MR | I5: abgerechnet | J5: 139 | K5: 46028 | L5: RE-2026-0003
A6: A-26-003 | B6: 46027 | C6: 10097 | D6: Berger, Ramona | E6: Teplitzer Straße 163 | F6: Heizungstausch | G6: Heizungsmodernisierung | H6: AY/KS | I6: abgerechnet | J6: 14903 | K6: 46045
A7: A-26-004 | B7: 05.01.2026 | C7: 10101 | D7: Seniorenresidenz Am Großen Garten gGmbH | E7: Tolkewitzer Straße 125a | F7: Notdienst | G7: Verstopfung Grundleitung | H7: Kowalski | I7: abgerechnet | J7: 268 | K7: 46030 | L7: RE-2026-0012
A8: A-26-005 | B8: 46031 | C8: 10019 | D8: Physiotherapie am Alaunpark | E8: Leipziger Straße 158b | F8: Wartung | G8: Wartung Gas-Brennwertkessel | H8: AY | I8: abgerechnet | J8: pauschal 139,- | K8: 46031
A9: A-26-006 | B9: 46034 | C9: 10030 | D9: Autohaus Pieschen GmbH | E9: Bergstraße 11 | F9: Heizungstausch | G9: Austausch Gaskessel gegen Brennwert | H9: MR/LW | I9: abgerechnet | J9: 15.178,00 € | K9: 46078
A10: A-26-007 | B10: 46034 | D10: Praxis Dr. med. dent. Lehmann | E10: Wiener Straße 33 | F10: Heizungstausch | G10: Austausch Gaskessel gegen Brennwert | H10: MR/LW | I10: abgerechnet | J10: 13245 | K10: 46083 | L10: RE-2026-0009, RE-2026-0067
A11: A-26-008 | B11: 46034 | C11: 10064 | D11: Engel, Grit | E11: Hechtstraße 35 | F11: Hydr. Abgleich | G11: Hydraulischer Abgleich | H11: DH | I11: abgerechnet | J11: 1358 | K11: 46036 | L11: RE-2026-0022
A12: A-26-009 | B12: 12/01/26 | C12: 10066 | D12: Fr. Petzold | E12: Louisenstraße 122 | F12: Notdienst | G12: Heizungsausfall Wochenende | H12: JK | I12: abgerechnet | J12: nach Aufwand | K12: 46035 | L12: RE-2026-0024
A13: A-26-010 | B13: 46034 | C13: 10070 | D13: Bäckerei Hoffmann | E13: Königsbrücker Straße 56 | F13: Reparatur | G13: Heizung ohne Funktion | H13: DH | I13: abgerechnet | J13: 923 | K13: 46036 | L13: RE-2026-0013
A14: A-26-011 | B14: 46034 | D14: Nadine Neumann | E14: Hechtstraße 176b | F14: Badsanierung | G14: Badumbau barrierefrei | H14: MR/LW | I14: abgerechnet | J14: 21082 | K14: 46058 | L14: RE-2026-0010, RE-2026-0049
A15: A-26-012 | B15: 46034 | C15: 10080 | D15: Tierarztpraxis Dr. Fiedler | E15: Pirnaer Landstraße 48 | F15: Wartung | G15: Wartung Gas-Brennwertkessel | H15: MR | I15: abgerechnet | J15: 149 | K15: 46036 | L15: RE-2026-0023
A16: A-26-013 | B16: 13.01.2026 | C16: 10024 | D16: Mirko Vogel | E16: Cossebauder Straße 10 | F16: Reparatur | G16: Heizung ohne Funktion | H16: JK | I16: abgerechnet | J16: nach Aufwand | K16: KW 3 | L16: RE-2026-0016
A17: A-26-014 | B17: 46035 | C17: 10070 | D17: Bäckerei Hoffmann | E17: Königsbrücker Straße 56 | F17: Wartung | G17: Wartung Ölheizung | H17: JK | I17: abgerechnet | J17: pauschal 139,- | K17: 46041
A18: A-26-015 | B18: 46035 | C18: 10110 | D18: Malerbetrieb Thiele | E18: Altenberger Straße 44 | F18: Wartung | G18: Wartung Ölheizung | H18: JK | I18: abgerechnet | J18: 189 | K18: 46036 | L18: RE-2026-0011
A19: A-26-016 | B19: 46035 | C19: 10128 | D19: Braun, Ute | E19: Meißner Landstraße 50 | F19: Wartung | G19: Wartung Ölheizung | H19: JK | I19: abgerechnet | J19: 139 | K19: 46038 | L19: RE-2026-0026
A20: A-26-017 | B20: 46036 | C20: 10103 | D20: Kita Sonnenblume | E20: Stauffenbergallee 22b | F20: Wartung | G20: Jahreswartung Gastherme | H20: JK | I20: abgerechnet | J20: 139,00 € | K20: 46041 | L20: RE-2026-0019
A21: A-26-018 | B21: 19.01.2026 | C21: 10016 | D21: Göbel, Sandra | E21: Bahnhofstraße 33 | F21: Wartung | G21: Wartung Wärmepumpe | H21: JK | I21: abgerechnet | J21: 139 | K21: 46042 | L21: RE-2026-0015
A22: A-26-019 | B22: 46041 | C22: 10082 | D22: Städtische Wohnungsgesellschaft Freital mbH | E22: Chemnitzer Straße 85 | F22: Wartung | G22: Wartung Ölheizung | H22: JK | I22: abgerechnet | J22: pauschal 149,- | K22: 46041 | L22: RE-2026-0025
A23: A-26-020 | B23: 46041 | C23: 10103 | D23: Kita Sonnenblume | E23: Stauffenbergallee 22b | F23: Wartung | G23: Wartung Wärmepumpe | H23: JK | I23: abgerechnet | J23: 139 | K23: KW 4 | L23: RE-2026-0031
A24: A-26-021 | B24: 46042 | D24: Seidel, Uwe | E24: Schandauer Straße 98 | F24: Wartung | G24: Wartung Gas-Brennwertkessel | H24: JK | I24: abgerechnet | J24: pauschal 139,- | K24: 46042 | L24: RE-2026-0020
A25: A-26-022 | B25: 20/01/26 | D25: Müller-Bau | E25: Radeburger Straße 5 | F25: Montage | G25: Einbau Enthärtungsanlage | H25: JK | I25: storniert | J25: 843
A26: A-26-023 | B26: 21.01.2026 | C26: 10030 | D26: Autohaus Pieschen GmbH | E26: Bergstraße 11 | F26: Montage | G26: Austausch Warmwasserspeicher | H26: JK | I26: abgerechnet | J26: nach Aufwand | K26: 46049 | L26: RE-2026-0038
A27: A-26-024 | B27: 46044 | C27: 10035 | D27: Café Neustadt UG | E27: Cossebauder Straße 153b | F27: Wartung | G27: Wartung Ölheizung | H27: JK | I27: abgerechnet | J27: 159 | K27: 46045 | L27: RE-2026-0027
A28: A-26-025 | B28: 46044 | C28: 10072 | D28: Kindergarten Elbspatzen e.V. | E28: Königsbrücker Straße 33b | F28: Reparatur | G28: Austausch Thermostatventil | H28: MR | I28: abgerechnet | J28: 578 | K28: 46045 | L28: RE-2026-0033
A29: A-26-026 | B29: 46045 | C29: 10075 | D29: Rainer Engel | E29: Nürnberger Straße 9 | F29: Reparatur | G29: Armatur tropft | H29: JK | I29: abgerechnet | J29: 534 | K29: 46051 | L29: RE-2026-0042
A30: A-26-027 | B30: 46045 | C30: 10121 | D30: Druckerei Lindner GmbH | E30: Wehlener Straße 135 | F30: Reparatur | G30: Druckverlust Heizung | H30: AY | I30: storniert
A31: A-26-028 | B31: 46048 | C31: 10027 | D31: Hausverwaltung Kröber | E31: Stauffenbergallee 98 | F31: Notdienst | G31: Heizungsausfall Wochenende | H31: JK | I31: abgerechnet | J31: 484 | K31: 46050 | L31: RE-2026-0029
A32: A-26-029 | B32: 46049 | C32: 10032 | D32: Uwe Grafe | E32: Kesselsdorfer Straße 150 | F32: Wartung | G32: Jahreswartung Gastherme | H32: DH | I32: abgerechnet | J32: 139 | K32: 46049 | L32: RE-2026-0041
A33: A-26-030 | B33: 46049 | C33: 10053 | D33: Ullrich, Anja | E33: Rudolf-Leonhard-Straße 114 | F33: Wartung | G33: Wartung Gas-Brennwertkessel | H33: AY | I33: abgerechnet | J33: 189 | K33: 46049 | L33: RE-2026-0035
A34: A-26-031 | B34: 46050 | C34: 10136 | D34: Werner, Susanne | E34: Cossebauder Straße 101a | F34: Wartung | G34: Wartung Gas-Brennwertkessel | H34: DH | I34: erledigt | J34: pauschal 139,- | K34: 46050
A35: A-26-032 | B35: 46051 | C35: 10024 | D35: Hr. Vogel | E35: Cossebauder Straße 10 | F35: Heizungstausch | G35: Einbau Wärmepumpe Luft/Wasser | H35: MR/KS | I35: abgerechnet | J35: 15862 | K35: 46079 | L35: RE-2026-0043, RE-2026-0071
A36: A-26-033 | B36: 29/01/26 | C36: 10056 | D36: Wohnungsbaugenossenschaft Johannstadt eG | E36: Leipziger Straße 20 | F36: Strangsanierung | G36: Strangsanierung Abwasser + TW | H36: MR/LW | I36: abgerechnet | J36: 41417 | K36: 46086
A37: A-26-034 | B37: 29.01.2026 | C37: 10067 | D37: Elektro Müller e.K. | E37: Pirnaer Landstraße 88 | F37: Reparatur | G37: Siphon undicht | H37: DH | I37: abgerechnet | J37: 959 | K37: 46052 | L37: RE-2026-0039
A38: A-26-035 | B38: 30.1.26 | C38: 10045 | D38: Müller Bau GmbH | E38: Radeburger Straße 5 | F38: Reparatur | G38: Spülkasten läuft nach | H38: AY | I38: abgerechnet | J38: 374 | K38: 46052 | L38: RE-2026-0032
A39: A-26-036 | B39: 46052 | C39: 10050 | D39: WEG-Verwaltung Blasewitz | E39: Chemnitzer Straße 19 | F39: Trinkwasser | G39: Spülung Trinkwasseranlage | H39: AY | I39: abgerechnet | J39: 420 | K39: 46058
A40: A-26-037 | B40: 46052 | C40: 10065 | D40: Wagner, Yvonne | E40: Louisenstraße 116a | F40: Montage | G40: Montage Heizkörper | H40: DH | I40: abgerechnet | J40: 532 | K40: 46058 | L40: RE-2026-0045
...

Sheet Auswertung
A1: Aufträge 2026 je Monteur und Monat
A3: Monteur | B3: Jan | C3: Feb | D3: Mär | E3: Apr | F3: Mai | G3: Jun | H3: Jul | I3: Aug | J3: Sep | K3: Okt | L3: Gesamt
A4: TB | B4: =COUNTIFS('2026'!H:H,"*TB*",'2026'!B:B,">="&DATE(2026,1,1),'2026'!B:B,"<"&DATE(2026,2,1)) -> 0 | C4: =COUNTIFS('2026'!H:H,"*TB*",'2026'!B:B,">="&DATE(2026,2,1),'2026'!B:B,"<"&DATE(2026,3,1)) -> 0 | D4: =COUNTIFS('2026'!H:H,"*TB*",'2026'!B:B,">="&DATE(2026,3,1),'2026'!B:B,"<"&DATE(2026,4,1)) -> 0 | E4: =COUNTIFS('2026'!H:H,"*TB*",'2026'!B:B,">="&DATE(2026,4,1),'2026'!B:B,"<"&DATE(2026,5,1)) -> 0 | F4: =COUNTIFS('2026'!H:H,"*TB*",'2026'!B:B,">="&DATE(2026,5,1),'2026'!B:B,"<"&DATE(2026,6,1)) -> 0 | G4: =COUNTIFS('2026'!H:H,"*TB*",'2026'!B:B,">="&DATE(2026,6,1),'2026'!B:B,"<"&DATE(2026,7,1)) -> 0 | H4: =COUNTIFS('2026'!H:H,"*TB*",'2026'!B:B,">="&DATE(2026,7,1),'2026'!B:B,"<"&DATE(2026,8,1)) -> 0 | I4: =COUNTIFS('2026'!H:H,"*TB*",'2026'!B:B,">="&DATE(2026,8,1),'2026'!B:B,"<"&DATE(2026,9,1)) -> 0 | J4: =COUNTIFS('2026'!H:H,"*TB*",'2026'!B:B,">="&DATE(2026,9,1),'2026'!B:B,"<"&DATE(2026,10,1)) -> 0 | K4: =COUNTIFS('2026'!H:H,"*TB*",'2026'!B:B,">="&DATE(2026,10,1),'2026'!B:B,"<"&DATE(2026,11,1)) -> 1 | L4: =SUM(B4:K4) -> 1
A5: JK | B5: =COUNTIFS('2026'!H:H,"*JK*",'2026'!B:B,">="&DATE(2026,1,1),'2026'!B:B,"<"&DATE(2026,2,1)) -> 16 | C5: =COUNTIFS('2026'!H:H,"*JK*",'2026'!B:B,">="&DATE(2026,2,1),'2026'!B:B,"<"&DATE(2026,3,1)) -> 7 | D5: =COUNTIFS('2026'!H:H,"*JK*",'2026'!B:B,">="&DATE(2026,3,1),'2026'!B:B,"<"&DATE(2026,4,1)) -> 7 | E5: =COUNTIFS('2026'!H:H,"*JK*",'2026'!B:B,">="&DATE(2026,4,1),'2026'!B:B,"<"&DATE(2026,5,1)) -> 9 | F5: =COUNTIFS('2026'!H:H,"*JK*",'2026'!B:B,">="&DATE(2026,5,1),'2026'!B:B,"<"&DATE(2026,6,1)) -> 12 | G5: =COUNTIFS('2026'!H:H,"*JK*",'2026'!B:B,">="&DATE(2026,6,1),'2026'!B:B,"<"&DATE(2026,7,1)) -> 10 | H5: =COUNTIFS('2026'!H:H,"*JK*",'2026'!B:B,">="&DATE(2026,7,1),'2026'!B:B,"<"&DATE(2026,8,1)) -> 5 | I5: =COUNTIFS('2026'!H:H,"*JK*",'2026'!B:B,">="&DATE(2026,8,1),'2026'!B:B,"<"&DATE(2026,9,1)) -> 6 | J5: =COUNTIFS('2026'!H:H,"*JK*",'2026'!B:B,">="&DATE(2026,9,1),'2026'!B:B,"<"&DATE(2026,10,1)) -> 19 | K5: =COUNTIFS('2026'!H:H,"*JK*",'2026'!B:B,">="&DATE(2026,10,1),'2026'!B:B,"<"&DATE(2026,11,1)) -> 4 | L5: =SUM(B5:K5) -> 95
A6: MR | B6: =COUNTIFS('2026'!H:H,"*MR*",'2026'!B:B,">="&DATE(2026,1,1),'2026'!B:B,"<"&DATE(2026,2,1)) -> 9 | C6: =COUNTIFS('2026'!H:H,"*MR*",'2026'!B:B,">="&DATE(2026,2,1),'2026'!B:B,"<"&DATE(2026,3,1)) -> 6 | D6: =COUNTIFS('2026'!H:H,"*MR*",'2026'!B:B,">="&DATE(2026,3,1),'2026'!B:B,"<"&DATE(2026,4,1)) -> 5 | E6: =COUNTIFS('2026'!H:H,"*MR*",'2026'!B:B,">="&DATE(2026,4,1),'2026'!B:B,"<"&DATE(2026,5,1)) -> 4 | F6: =COUNTIFS('2026'!H:H,"*MR*",'2026'!B:B,">="&DATE(2026,5,1),'2026'!B:B,"<"&DATE(2026,6,1)) -> 6 | G6: =COUNTIFS('2026'!H:H,"*MR*",'2026'!B:B,">="&DATE(2026,6,1),'2026'!B:B,"<"&DATE(2026,7,1)) -> 7 | H6: =COUNTIFS('2026'!H:H,"*MR*",'2026'!B:B,">="&DATE(2026,7,1),'2026'!B:B,"<"&DATE(2026,8,1)) -> 11 | I6: =COUNTIFS('2026'!H:H,"*MR*",'2026'!B:B,">="&DATE(2026,8,1),'2026'!B:B,"<"&DATE(2026,9,1)) -> 5 | J6: =COUNTIFS('2026'!H:H,"*MR*",'2026'!B:B,">="&DATE(2026,9,1),'2026'!B:B,"<"&DATE(2026,10,1)) -> 13 | K6: =COUNTIFS('2026'!H:H,"*MR*",'2026'!B:B,">="&DATE(2026,10,1),'2026'!B:B,"<"&DATE(2026,11,1)) -> 2 | L6: =SUM(B6:K6) -> 68
A7: DH | B7: =COUNTIFS('2026'!H:H,"*DH*",'2026'!B:B,">="&DATE(2026,1,1),'2026'!B:B,"<"&DATE(2026,2,1)) -> 6 | C7: =COUNTIFS('2026'!H:H,"*DH*",'2026'!B:B,">="&DATE(2026,2,1),'2026'!B:B,"<"&DATE(2026,3,1)) -> 6 | D7: =COUNTIFS('2026'!H:H,"*DH*",'2026'!B:B,">="&DATE(2026,3,1),'2026'!B:B,"<"&DATE(2026,4,1)) -> 5 | E7: =COUNTIFS('2026'!H:H,"*DH*",'2026'!B:B,">="&DATE(2026,4,1),'2026'!B:B,"<"&DATE(2026,5,1)) -> 3 | F7: =COUNTIFS('2026'!H:H,"*DH*",'2026'!B:B,">="&DATE(2026,5,1),'2026'!B:B,"<"&DATE(2026,6,1)) -> 5 | G7: =COUNTIFS('2026'!H:H,"*DH*",'2026'!B:B,">="&DATE(2026,6,1),'2026'!B:B,"<"&DATE(2026,7,1)) -> 6 | H7: =COUNTIFS('2026'!H:H,"*DH*",'2026'!B:B,">="&DATE(2026,7,1),'2026'!B:B,"<"&DATE(2026,8,1)) -> 5 | I7: =COUNTIFS('2026'!H:H,"*DH*",'2026'!B:B,">="&DATE(2026,8,1),'2026'!B:B,"<"&DATE(2026,9,1)) -> 3 | J7: =COUNTIFS('2026'!H:H,"*DH*",'2026'!B:B,">="&DATE(2026,9,1),'2026'!B:B,"<"&DATE(2026,10,1)) -> 5 | K7: =COUNTIFS('2026'!H:H,"*DH*",'2026'!B:B,">="&DATE(2026,10,1),'2026'!B:B,"<"&DATE(2026,11,1)) -> 4 | L7: =SUM(B7:K7) -> 48
A8: AY | B8: =COUNTIFS('2026'!H:H,"*AY*",'2026'!B:B,">="&DATE(2026,1,1),'2026'!B:B,"<"&DATE(2026,2,1)) -> 7 | C8: =COUNTIFS('2026'!H:H,"*AY*",'2026'!B:B,">="&DATE(2026,2,1),'2026'!B:B,"<"&DATE(2026,3,1)) -> 2 | D8: =COUNTIFS('2026'!H:H,"*AY*",'2026'!B:B,">="&DATE(2026,3,1),'2026'!B:B,"<"&DATE(2026,4,1)) -> 8 | E8: =COUNTIFS('2026'!H:H,"*AY*",'2026'!B:B,">="&DATE(2026,4,1),'2026'!B:B,"<"&DATE(2026,5,1)) -> 2 | F8: =COUNTIFS('2026'!H:H,"*AY*",'2026'!B:B,">="&DATE(2026,5,1),'2026'!B:B,"<"&DATE(2026,6,1)) -> 3 | G8: =COUNTIFS('2026'!H:H,"*AY*",'2026'!B:B,">="&DATE(2026,6,1),'2026'!B:B,"<"&DATE(2026,7,1)) -> 11 | H8: =COUNTIFS('2026'!H:H,"*AY*",'2026'!B:B,">="&DATE(2026,7,1),'2026'!B:B,"<"&DATE(2026,8,1)) -> 10 | I8: =COUNTIFS('2026'!H:H,"*AY*",'2026'!B:B,">="&DATE(2026,8,1),'2026'!B:B,"<"&DATE(2026,9,1)) -> 4 | J8: =COUNTIFS('2026'!H:H,"*AY*",'2026'!B:B,">="&DATE(2026,9,1),'2026'!B:B,"<"&DATE(2026,10,1)) -> 7 | K8: =COUNTIFS('2026'!H:H,"*AY*",'2026'!B:B,">="&DATE(2026,10,1),'2026'!B:B,"<"&DATE(2026,11,1)) -> 0 | L8: =SUM(B8:K8) -> 54
